<?xml version="1.0" ?>
<sdf version="1.6">
  <model name="simple_yolo_tracker">

    <!-- Base Link -->
    <link name="base_link">
      <pose>0 0 0 0 0 0</pose>
      <inertial>
        <mass>2.0</mass>
        <inertia>
          <ixx>0.01</ixx>
          <iyy>0.02</iyy>
          <izz>0.02</izz>
          <ixy>0.0</ixy>
          <ixz>0.0</ixz>
          <iyz>0.0</iyz>
        </inertia>
      </inertial>
      <collision name="base_collision">
        <geometry>
          <box>
            <size>0.3 0.2 0.05</size>
          </box>
        </geometry>
      </collision>
      <visual name="base_visual">
        <geometry>
          <box>
            <size>0.3 0.2 0.05</size>
          </box>
        </geometry>
        <material>
          <ambient>0.6 0.6 0.6 1</ambient>
          <diffuse>0.6 0.6 0.6 1</diffuse>
        </material>
      </visual>
    </link>

    <!-- Left Wheel -->
    <link name="left_wheel">
      <pose>0.0 0.11 0.05 0 0 1.5708</pose>
      <inertial>
        <mass>0.3</mass>
        <inertia>
          <ixx>0.0005</ixx>
          <iyy>0.0005</iyy>
          <izz>0.0005</izz>
          <ixy>0.0</ixy>
          <ixz>0.0</ixz>
          <iyz>0.0</iyz>
        </inertia>
      </inertial>
      <collision name="left_wheel_collision">
        <geometry>
          <cylinder>
            <radius>0.05</radius>
            <length>0.04</length>
          </cylinder>
        </geometry>
      </collision>
      <visual name="left_wheel_visual">
        <geometry>
          <cylinder>
            <radius>0.05</radius>
            <length>0.04</length>
          </cylinder>
        </geometry>
        <material>
          <ambient>0.0 0.0 0.0 1</ambient>
          <diffuse>0.0 0.0 0.0 1</diffuse>
        </material>
      </visual>
    </link>
    <joint name="left_wheel_joint" type="revolute">
      <parent>base_link</parent>
      <child>left_wheel</child>
      <pose>0.0 0.11 0.05 0 0 0</pose>
      <axis>
        <xyz>0 1 0</xyz>
        <limit>
          <lower>-1e16</lower>
          <upper>1e16</upper>
        </limit>
      </axis>
    </joint>

    <!-- Right Wheel -->
    <link name="right_wheel">
      <pose>0.0 -0.11 0.05 0 0 1.5708</pose>
      <inertial>
        <mass>0.3</mass>
        <inertia>
          <ixx>0.0005</ixx>
          <iyy>0.0005</iyy>
          <izz>0.0005</izz>
          <ixy>0.0</ixy>
          <ixz>0.0</ixz>
          <iyz>0.0</iyz>
        </inertia>
      </inertial>
      <collision name="right_wheel_collision">
        <geometry>
          <cylinder>
            <radius>0.05</radius>
            <length>0.04</length>
          </cylinder>
        </geometry>
      </collision>
      <visual name="right_wheel_visual">
        <geometry>
          <cylinder>
            <radius>0.05</radius>
            <length>0.04</length>
          </cylinder>
        </geometry>
        <material>
          <ambient>0.0 0.0 0.0 1</ambient>
          <diffuse>0.0 0.0 0.0 1</diffuse>
        </material>
      </visual>
    </link>
    <joint name="right_wheel_joint" type="revolute">
      <parent>base_link</parent>
      <child>right_wheel</child>
      <pose>0.0 -0.11 0.05 0 0 0</pose>
      <axis>
        <xyz>0 1 0</xyz>
        <limit>
          <lower>-1e16</lower>
          <upper>1e16</upper>
        </limit>
      </axis>
    </joint>

    <!-- Camera -->
    <link name="camera_link">
      <pose>0.15 0 0.09 0 0 0</pose>
      <inertial>
        <mass>0.1</mass>
        <inertia>
          <ixx>0.0001</ixx>
          <iyy>0.0001</iyy>
          <izz>0.0001</izz>
          <ixy>0.0</ixy>
          <ixz>0.0</ixz>
          <iyz>0.0</iyz>
        </inertia>
      </inertial>
      <collision name="camera_collision">
        <geometry>
          <box>
            <size>0.04 0.04 0.04</size>
          </box>
        </geometry>
      </collision>
      <visual name="camera_visual">
        <geometry>
          <box>
            <size>0.04 0.04 0.04</size>
          </box>
        </geometry>
        <material>
          <ambient>0.0 0.2 1.0 1</ambient>
          <diffuse>0.0 0.2 1.0 1</diffuse>
        </material>
      </visual>
      <!-- Gazebo Camera Sensor Plugin -->
      <sensor name="camera" type="camera">
        <always_on>1</always_on>
        <update_rate>30</update_rate>
        <visualize>true</visualize>
        <camera>
          <horizontal_fov>1.047</horizontal_fov>
          <image>
            <width>640</width>
            <height>480</height>
            <format>R8G8B8</format>
          </image>
          <clip>
            <near>0.1</near>
            <far>100</far>
          </clip>
        </camera>
        <plugin name="camera_controller" filename="libgazebo_ros_camera.so">
          <ros>
            <namespace>/</namespace>
            <remapping>image_raw:=/camera/image_raw</remapping>
          </ros>
          <camera_name>camera</camera_name>
          <frame_name>camera_link</frame_name>
        </plugin>
      </sensor>
    </link>
    <joint name="camera_joint" type="fixed">
      <parent>base_link</parent>
      <child>camera_link</child>
      <pose>0.15 0 0.09 0 0 0</pose>
    </joint>
  </model>
</sdf>